30.05 10:45:03> Admin Command Error: manage.py force_rate_trips
Traceback (most recent call last):
  File "manage.py", line 26, in <module>
    execute_from_command_line(sys.argv)
  File "/Users/lapshov/Documents/dve/lib/python3.4/site-packages/django/core/management/__init__.py", line 367, in execute_from_command_line
    utility.execute()
  File "/Users/lapshov/Documents/dve/lib/python3.4/site-packages/django/core/management/__init__.py", line 359, in execute
    self.fetch_command(subcommand).run_from_argv(self.argv)
  File "/Users/lapshov/Documents/dve/lib/python3.4/site-packages/django/core/management/base.py", line 294, in run_from_argv
    self.execute(*args, **cmd_options)
  File "/Users/lapshov/Documents/dve/lib/python3.4/site-packages/django/core/management/base.py", line 345, in execute
    output = self.handle(*args, **options)
  File "/Users/lapshov/Documents/dve/enot/enot_app/management/commands/force_rate_trips.py", line 25, in handle
    t.supply()
  File "/Users/lapshov/Documents/dve/enot/enot_app/models.py", line 364, in supply
    self.days_to_text = "через "+str(self.days_to)+" "+russian_plurals('день', self.days_to)
TypeError: Can't convert 'NoneType' object to str implicitly
30.05 10:46:21> Admin Command Error: manage.py force_rate_trips
Traceback (most recent call last):
  File "manage.py", line 26, in <module>
    execute_from_command_line(sys.argv)
  File "/Users/lapshov/Documents/dve/lib/python3.4/site-packages/django/core/management/__init__.py", line 367, in execute_from_command_line
    utility.execute()
  File "/Users/lapshov/Documents/dve/lib/python3.4/site-packages/django/core/management/__init__.py", line 359, in execute
    self.fetch_command(subcommand).run_from_argv(self.argv)
  File "/Users/lapshov/Documents/dve/lib/python3.4/site-packages/django/core/management/base.py", line 294, in run_from_argv
    self.execute(*args, **cmd_options)
  File "/Users/lapshov/Documents/dve/lib/python3.4/site-packages/django/core/management/base.py", line 345, in execute
    output = self.handle(*args, **options)
  File "/Users/lapshov/Documents/dve/enot/enot_app/management/commands/force_rate_trips.py", line 25, in handle
    t.supply()
  File "/Users/lapshov/Documents/dve/enot/enot_app/models.py", line 364, in supply
    self.days_to_text = "через "+str(self.days_to)+" "+russian_plurals('день', self.days_to)
TypeError: Can't convert 'NoneType' object to str implicitly
30.05 10:49:46> Admin Command Error: manage.py force_rate_trips
Traceback (most recent call last):
  File "manage.py", line 26, in <module>
    execute_from_command_line(sys.argv)
  File "/Users/lapshov/Documents/dve/lib/python3.4/site-packages/django/core/management/__init__.py", line 367, in execute_from_command_line
    utility.execute()
  File "/Users/lapshov/Documents/dve/lib/python3.4/site-packages/django/core/management/__init__.py", line 359, in execute
    self.fetch_command(subcommand).run_from_argv(self.argv)
  File "/Users/lapshov/Documents/dve/lib/python3.4/site-packages/django/core/management/base.py", line 294, in run_from_argv
    self.execute(*args, **cmd_options)
  File "/Users/lapshov/Documents/dve/lib/python3.4/site-packages/django/core/management/base.py", line 345, in execute
    output = self.handle(*args, **options)
  File "/Users/lapshov/Documents/dve/enot/enot_app/management/commands/force_rate_trips.py", line 25, in handle
    t.supply()
  File "/Users/lapshov/Documents/dve/enot/enot_app/models.py", line 364, in supply
    self.days_to_text = "через "+str(self.days_to)+" "+russian_plurals('день', self.days_to)
TypeError: Can't convert 'NoneType' object to str implicitly
30.05 10:53:42> Admin Command Error: manage.py force_rate_trips
Traceback (most recent call last):
  File "manage.py", line 26, in <module>
    execute_from_command_line(sys.argv)
  File "/Users/lapshov/Documents/dve/lib/python3.4/site-packages/django/core/management/__init__.py", line 367, in execute_from_command_line
    utility.execute()
  File "/Users/lapshov/Documents/dve/lib/python3.4/site-packages/django/core/management/__init__.py", line 359, in execute
    self.fetch_command(subcommand).run_from_argv(self.argv)
  File "/Users/lapshov/Documents/dve/lib/python3.4/site-packages/django/core/management/base.py", line 294, in run_from_argv
    self.execute(*args, **cmd_options)
  File "/Users/lapshov/Documents/dve/lib/python3.4/site-packages/django/core/management/base.py", line 345, in execute
    output = self.handle(*args, **options)
  File "/Users/lapshov/Documents/dve/enot/enot_app/management/commands/force_rate_trips.py", line 25, in handle
    t.supply()
  File "/Users/lapshov/Documents/dve/enot/enot_app/models.py", line 364, in supply
    self.days_to_text = "через "+str(self.days_to)+" "+russian_plurals('день', self.days_to)
TypeError: Can't convert 'NoneType' object to str implicitly
30.05 10:53:57> Admin Command Error: manage.py force_rate_trips
Traceback (most recent call last):
  File "manage.py", line 26, in <module>
    execute_from_command_line(sys.argv)
  File "/Users/lapshov/Documents/dve/lib/python3.4/site-packages/django/core/management/__init__.py", line 367, in execute_from_command_line
    utility.execute()
  File "/Users/lapshov/Documents/dve/lib/python3.4/site-packages/django/core/management/__init__.py", line 359, in execute
    self.fetch_command(subcommand).run_from_argv(self.argv)
  File "/Users/lapshov/Documents/dve/lib/python3.4/site-packages/django/core/management/base.py", line 294, in run_from_argv
    self.execute(*args, **cmd_options)
  File "/Users/lapshov/Documents/dve/lib/python3.4/site-packages/django/core/management/base.py", line 345, in execute
    output = self.handle(*args, **options)
  File "/Users/lapshov/Documents/dve/enot/enot_app/management/commands/force_rate_trips.py", line 25, in handle
    t.supply()
  File "/Users/lapshov/Documents/dve/enot/enot_app/models.py", line 364, in supply
    self.days_to_text = "через "+str(self.days_to)+" "+russian_plurals('день', self.days_to)
TypeError: Can't convert 'NoneType' object to str implicitly
30.05 10:55:38> Admin Command Error: manage.py force_rate_trips
Traceback (most recent call last):
  File "manage.py", line 26, in <module>
    execute_from_command_line(sys.argv)
  File "/Users/lapshov/Documents/dve/lib/python3.4/site-packages/django/core/management/__init__.py", line 367, in execute_from_command_line
    utility.execute()
  File "/Users/lapshov/Documents/dve/lib/python3.4/site-packages/django/core/management/__init__.py", line 359, in execute
    self.fetch_command(subcommand).run_from_argv(self.argv)
  File "/Users/lapshov/Documents/dve/lib/python3.4/site-packages/django/core/management/base.py", line 294, in run_from_argv
    self.execute(*args, **cmd_options)
  File "/Users/lapshov/Documents/dve/lib/python3.4/site-packages/django/core/management/base.py", line 345, in execute
    output = self.handle(*args, **options)
  File "/Users/lapshov/Documents/dve/enot/enot_app/management/commands/force_rate_trips.py", line 26, in handle
    t.supply()
  File "/Users/lapshov/Documents/dve/enot/enot_app/models.py", line 364, in supply
    self.days_to_text = "через "+str(self.days_to)+" "+russian_plurals('день', self.days_to)
TypeError: Can't convert 'NoneType' object to str implicitly
30.05 10:56:46> Admin Command Error: manage.py force_rate_trips
Traceback (most recent call last):
  File "manage.py", line 26, in <module>
    execute_from_command_line(sys.argv)
  File "/Users/lapshov/Documents/dve/lib/python3.4/site-packages/django/core/management/__init__.py", line 367, in execute_from_command_line
    utility.execute()
  File "/Users/lapshov/Documents/dve/lib/python3.4/site-packages/django/core/management/__init__.py", line 359, in execute
    self.fetch_command(subcommand).run_from_argv(self.argv)
  File "/Users/lapshov/Documents/dve/lib/python3.4/site-packages/django/core/management/base.py", line 294, in run_from_argv
    self.execute(*args, **cmd_options)
  File "/Users/lapshov/Documents/dve/lib/python3.4/site-packages/django/core/management/base.py", line 345, in execute
    output = self.handle(*args, **options)
  File "/Users/lapshov/Documents/dve/enot/enot_app/management/commands/force_rate_trips.py", line 27, in handle
    t.supply()
  File "/Users/lapshov/Documents/dve/enot/enot_app/models.py", line 364, in supply
    self.days_to_text = "через "+str(self.days_to)+" "+russian_plurals('день', self.days_to)
TypeError: Can't convert 'NoneType' object to str implicitly
30.05 10:57:22> Admin Command Error: manage.py force_rate_trips
Traceback (most recent call last):
  File "manage.py", line 26, in <module>
    execute_from_command_line(sys.argv)
  File "/Users/lapshov/Documents/dve/lib/python3.4/site-packages/django/core/management/__init__.py", line 367, in execute_from_command_line
    utility.execute()
  File "/Users/lapshov/Documents/dve/lib/python3.4/site-packages/django/core/management/__init__.py", line 359, in execute
    self.fetch_command(subcommand).run_from_argv(self.argv)
  File "/Users/lapshov/Documents/dve/lib/python3.4/site-packages/django/core/management/base.py", line 294, in run_from_argv
    self.execute(*args, **cmd_options)
  File "/Users/lapshov/Documents/dve/lib/python3.4/site-packages/django/core/management/base.py", line 345, in execute
    output = self.handle(*args, **options)
  File "/Users/lapshov/Documents/dve/enot/enot_app/management/commands/force_rate_trips.py", line 29, in handle
    t.supply()
  File "/Users/lapshov/Documents/dve/enot/enot_app/models.py", line 364, in supply
    self.days_to_text = "через "+str(self.days_to)+" "+russian_plurals('день', self.days_to)
TypeError: Can't convert 'NoneType' object to str implicitly
30.05 11:00:23> Admin Command Error: manage.py force_rate_trips
Traceback (most recent call last):
  File "manage.py", line 26, in <module>
    execute_from_command_line(sys.argv)
  File "/Users/lapshov/Documents/dve/lib/python3.4/site-packages/django/core/management/__init__.py", line 367, in execute_from_command_line
    utility.execute()
  File "/Users/lapshov/Documents/dve/lib/python3.4/site-packages/django/core/management/__init__.py", line 359, in execute
    self.fetch_command(subcommand).run_from_argv(self.argv)
  File "/Users/lapshov/Documents/dve/lib/python3.4/site-packages/django/core/management/base.py", line 294, in run_from_argv
    self.execute(*args, **cmd_options)
  File "/Users/lapshov/Documents/dve/lib/python3.4/site-packages/django/core/management/base.py", line 345, in execute
    output = self.handle(*args, **options)
  File "/Users/lapshov/Documents/dve/enot/enot_app/management/commands/force_rate_trips.py", line 29, in handle
    t.supply()
  File "/Users/lapshov/Documents/dve/enot/enot_app/models.py", line 366, in supply
    self.days_to_text = "через "+str(self.days_to)+" "+russian_plurals('день', self.days_to)
TypeError: Can't convert 'NoneType' object to str implicitly
30.05 11:01:47> Admin Command Error: manage.py force_rate_trips
Traceback (most recent call last):
  File "manage.py", line 26, in <module>
    execute_from_command_line(sys.argv)
  File "/Users/lapshov/Documents/dve/lib/python3.4/site-packages/django/core/management/__init__.py", line 367, in execute_from_command_line
    utility.execute()
  File "/Users/lapshov/Documents/dve/lib/python3.4/site-packages/django/core/management/__init__.py", line 359, in execute
    self.fetch_command(subcommand).run_from_argv(self.argv)
  File "/Users/lapshov/Documents/dve/lib/python3.4/site-packages/django/core/management/base.py", line 294, in run_from_argv
    self.execute(*args, **cmd_options)
  File "/Users/lapshov/Documents/dve/lib/python3.4/site-packages/django/core/management/base.py", line 345, in execute
    output = self.handle(*args, **options)
  File "/Users/lapshov/Documents/dve/enot/enot_app/management/commands/force_rate_trips.py", line 29, in handle
    t.supply()
  File "/Users/lapshov/Documents/dve/enot/enot_app/models.py", line 365, in supply
    self.days_to_text = "через "+str(self.days_to)+" "+russian_plurals('день', self.days_to)
TypeError: Can't convert 'NoneType' object to str implicitly
30.05 12:13:16> Admin Command Error: manage.py tmp_find_places
Traceback (most recent call last):
  File "manage.py", line 26, in <module>
    execute_from_command_line(sys.argv)
  File "/Users/lapshov/Documents/dve/lib/python3.4/site-packages/django/core/management/__init__.py", line 367, in execute_from_command_line
    utility.execute()
  File "/Users/lapshov/Documents/dve/lib/python3.4/site-packages/django/core/management/__init__.py", line 359, in execute
    self.fetch_command(subcommand).run_from_argv(self.argv)
  File "/Users/lapshov/Documents/dve/lib/python3.4/site-packages/django/core/management/base.py", line 294, in run_from_argv
    self.execute(*args, **cmd_options)
  File "/Users/lapshov/Documents/dve/lib/python3.4/site-packages/django/core/management/base.py", line 345, in execute
    output = self.handle(*args, **options)
  File "/Users/lapshov/Documents/dve/enot/enot_app/management/commands/tmp_find_places.py", line 20, in handle
    ap.tmp_find_place()
  File "/Users/lapshov/Documents/dve/enot/enot_app/models.py", line 114, in tmp_find_place
    p = GPlace.objects.get(city_code=self.city_code)
  File "/Users/lapshov/Documents/dve/lib/python3.4/site-packages/django/db/models/manager.py", line 85, in manager_method
    return getattr(self.get_queryset(), name)(*args, **kwargs)
  File "/Users/lapshov/Documents/dve/lib/python3.4/site-packages/django/db/models/query.py", line 389, in get
    (self.model._meta.object_name, num)
enot_app.models.MultipleObjectsReturned: get() returned more than one GPlace -- it returned 2!
30.05 12:24:14> Admin Command Error: manage.py tmp_find_places
Traceback (most recent call last):
  File "manage.py", line 26, in <module>
    execute_from_command_line(sys.argv)
  File "/Users/lapshov/Documents/dve/lib/python3.4/site-packages/django/core/management/__init__.py", line 367, in execute_from_command_line
    utility.execute()
  File "/Users/lapshov/Documents/dve/lib/python3.4/site-packages/django/core/management/__init__.py", line 341, in execute
    django.setup()
  File "/Users/lapshov/Documents/dve/lib/python3.4/site-packages/django/__init__.py", line 27, in setup
    apps.populate(settings.INSTALLED_APPS)
  File "/Users/lapshov/Documents/dve/lib/python3.4/site-packages/django/apps/registry.py", line 108, in populate
    app_config.import_models(all_models)
  File "/Users/lapshov/Documents/dve/lib/python3.4/site-packages/django/apps/config.py", line 199, in import_models
    self.models_module = import_module(models_module_name)
  File "/Users/lapshov/Documents/dve/lib/python3.4/importlib/__init__.py", line 109, in import_module
    return _bootstrap._gcd_import(name[level:], package, level)
  File "<frozen importlib._bootstrap>", line 2254, in _gcd_import
  File "<frozen importlib._bootstrap>", line 2237, in _find_and_load
  File "<frozen importlib._bootstrap>", line 2226, in _find_and_load_unlocked
  File "<frozen importlib._bootstrap>", line 1200, in _load_unlocked
  File "<frozen importlib._bootstrap>", line 1129, in _exec
  File "<frozen importlib._bootstrap>", line 1467, in exec_module
  File "<frozen importlib._bootstrap>", line 1572, in get_code
  File "<frozen importlib._bootstrap>", line 1532, in source_to_code
  File "<frozen importlib._bootstrap>", line 321, in _call_with_frames_removed
  File "/Users/lapshov/Documents/dve/enot/enot_app/models.py", line 117
    except GPlace.MultipleObjectsReturned:
         ^
IndentationError: expected an indented block
