24.05 15:27:01> Admin Command Error: manage.py migrate
Traceback (most recent call last):
  File "/Users/lapshov/Documents/dve/lib/python3.4/site-packages/django/db/backends/utils.py", line 64, in execute
    return self.cursor.execute(sql, params)
  File "/Users/lapshov/Documents/dve/lib/python3.4/site-packages/django/db/backends/mysql/base.py", line 110, in execute
    return self.cursor.execute(query, args)
  File "/Users/lapshov/Documents/dve/lib/python3.4/site-packages/MySQLdb/cursors.py", line 250, in execute
    self.errorhandler(self, exc, value)
  File "/Users/lapshov/Documents/dve/lib/python3.4/site-packages/MySQLdb/connections.py", line 42, in defaulterrorhandler
    raise errorvalue
  File "/Users/lapshov/Documents/dve/lib/python3.4/site-packages/MySQLdb/cursors.py", line 247, in execute
    res = self._query(query)
  File "/Users/lapshov/Documents/dve/lib/python3.4/site-packages/MySQLdb/cursors.py", line 411, in _query
    rowcount = self._do_query(q)
  File "/Users/lapshov/Documents/dve/lib/python3.4/site-packages/MySQLdb/cursors.py", line 374, in _do_query
    db.query(q)
  File "/Users/lapshov/Documents/dve/lib/python3.4/site-packages/MySQLdb/connections.py", line 270, in query
    _mysql.connection.query(self, query)
_mysql_exceptions.OperationalError: (1061, "Duplicate key name 'enot_app_subscriber_email_ea48cecc_uniq'")

The above exception was the direct cause of the following exception:

Traceback (most recent call last):
  File "manage.py", line 26, in <module>
    execute_from_command_line(sys.argv)
  File "/Users/lapshov/Documents/dve/lib/python3.4/site-packages/django/core/management/__init__.py", line 367, in execute_from_command_line
    utility.execute()
  File "/Users/lapshov/Documents/dve/lib/python3.4/site-packages/django/core/management/__init__.py", line 359, in execute
    self.fetch_command(subcommand).run_from_argv(self.argv)
  File "/Users/lapshov/Documents/dve/lib/python3.4/site-packages/django/core/management/base.py", line 294, in run_from_argv
    self.execute(*args, **cmd_options)
  File "/Users/lapshov/Documents/dve/lib/python3.4/site-packages/django/core/management/base.py", line 345, in execute
    output = self.handle(*args, **options)
  File "/Users/lapshov/Documents/dve/lib/python3.4/site-packages/django/core/management/commands/migrate.py", line 204, in handle
    fake_initial=fake_initial,
  File "/Users/lapshov/Documents/dve/lib/python3.4/site-packages/django/db/migrations/executor.py", line 115, in migrate
    state = self._migrate_all_forwards(state, plan, full_plan, fake=fake, fake_initial=fake_initial)
  File "/Users/lapshov/Documents/dve/lib/python3.4/site-packages/django/db/migrations/executor.py", line 145, in _migrate_all_forwards
    state = self.apply_migration(state, migration, fake=fake, fake_initial=fake_initial)
  File "/Users/lapshov/Documents/dve/lib/python3.4/site-packages/django/db/migrations/executor.py", line 244, in apply_migration
    state = migration.apply(state, schema_editor)
  File "/Users/lapshov/Documents/dve/lib/python3.4/site-packages/django/db/migrations/migration.py", line 129, in apply
    operation.database_forwards(self.app_label, schema_editor, old_state, project_state)
  File "/Users/lapshov/Documents/dve/lib/python3.4/site-packages/django/db/migrations/operations/fields.py", line 204, in database_forwards
    schema_editor.alter_field(from_model, from_field, to_field)
  File "/Users/lapshov/Documents/dve/lib/python3.4/site-packages/django/db/backends/base/schema.py", line 495, in alter_field
    old_db_params, new_db_params, strict)
  File "/Users/lapshov/Documents/dve/lib/python3.4/site-packages/django/db/backends/base/schema.py", line 678, in _alter_field
    self.execute(self._create_unique_sql(model, [new_field.column]))
  File "/Users/lapshov/Documents/dve/lib/python3.4/site-packages/django/db/backends/base/schema.py", line 112, in execute
    cursor.execute(sql, params)
  File "/Users/lapshov/Documents/dve/lib/python3.4/site-packages/django/db/backends/utils.py", line 79, in execute
    return super(CursorDebugWrapper, self).execute(sql, params)
  File "/Users/lapshov/Documents/dve/lib/python3.4/site-packages/django/db/backends/utils.py", line 64, in execute
    return self.cursor.execute(sql, params)
  File "/Users/lapshov/Documents/dve/lib/python3.4/site-packages/django/db/utils.py", line 94, in __exit__
    six.reraise(dj_exc_type, dj_exc_value, traceback)
  File "/Users/lapshov/Documents/dve/lib/python3.4/site-packages/django/utils/six.py", line 685, in reraise
    raise value.with_traceback(tb)
  File "/Users/lapshov/Documents/dve/lib/python3.4/site-packages/django/db/backends/utils.py", line 64, in execute
    return self.cursor.execute(sql, params)
  File "/Users/lapshov/Documents/dve/lib/python3.4/site-packages/django/db/backends/mysql/base.py", line 110, in execute
    return self.cursor.execute(query, args)
  File "/Users/lapshov/Documents/dve/lib/python3.4/site-packages/MySQLdb/cursors.py", line 250, in execute
    self.errorhandler(self, exc, value)
  File "/Users/lapshov/Documents/dve/lib/python3.4/site-packages/MySQLdb/connections.py", line 42, in defaulterrorhandler
    raise errorvalue
  File "/Users/lapshov/Documents/dve/lib/python3.4/site-packages/MySQLdb/cursors.py", line 247, in execute
    res = self._query(query)
  File "/Users/lapshov/Documents/dve/lib/python3.4/site-packages/MySQLdb/cursors.py", line 411, in _query
    rowcount = self._do_query(q)
  File "/Users/lapshov/Documents/dve/lib/python3.4/site-packages/MySQLdb/cursors.py", line 374, in _do_query
    db.query(q)
  File "/Users/lapshov/Documents/dve/lib/python3.4/site-packages/MySQLdb/connections.py", line 270, in query
    _mysql.connection.query(self, query)
django.db.utils.OperationalError: (1061, "Duplicate key name 'enot_app_subscriber_email_ea48cecc_uniq'")
24.05 15:28:39> Admin Command Error: manage.py migrate
Traceback (most recent call last):
  File "/Users/lapshov/Documents/dve/lib/python3.4/site-packages/django/db/backends/utils.py", line 64, in execute
    return self.cursor.execute(sql, params)
  File "/Users/lapshov/Documents/dve/lib/python3.4/site-packages/django/db/backends/mysql/base.py", line 110, in execute
    return self.cursor.execute(query, args)
  File "/Users/lapshov/Documents/dve/lib/python3.4/site-packages/MySQLdb/cursors.py", line 250, in execute
    self.errorhandler(self, exc, value)
  File "/Users/lapshov/Documents/dve/lib/python3.4/site-packages/MySQLdb/connections.py", line 42, in defaulterrorhandler
    raise errorvalue
  File "/Users/lapshov/Documents/dve/lib/python3.4/site-packages/MySQLdb/cursors.py", line 247, in execute
    res = self._query(query)
  File "/Users/lapshov/Documents/dve/lib/python3.4/site-packages/MySQLdb/cursors.py", line 411, in _query
    rowcount = self._do_query(q)
  File "/Users/lapshov/Documents/dve/lib/python3.4/site-packages/MySQLdb/cursors.py", line 374, in _do_query
    db.query(q)
  File "/Users/lapshov/Documents/dve/lib/python3.4/site-packages/MySQLdb/connections.py", line 270, in query
    _mysql.connection.query(self, query)
_mysql_exceptions.OperationalError: (1061, "Duplicate key name 'enot_app_subscriber_email_ea48cecc_uniq'")

The above exception was the direct cause of the following exception:

Traceback (most recent call last):
  File "manage.py", line 26, in <module>
    execute_from_command_line(sys.argv)
  File "/Users/lapshov/Documents/dve/lib/python3.4/site-packages/django/core/management/__init__.py", line 367, in execute_from_command_line
    utility.execute()
  File "/Users/lapshov/Documents/dve/lib/python3.4/site-packages/django/core/management/__init__.py", line 359, in execute
    self.fetch_command(subcommand).run_from_argv(self.argv)
  File "/Users/lapshov/Documents/dve/lib/python3.4/site-packages/django/core/management/base.py", line 294, in run_from_argv
    self.execute(*args, **cmd_options)
  File "/Users/lapshov/Documents/dve/lib/python3.4/site-packages/django/core/management/base.py", line 345, in execute
    output = self.handle(*args, **options)
  File "/Users/lapshov/Documents/dve/lib/python3.4/site-packages/django/core/management/commands/migrate.py", line 204, in handle
    fake_initial=fake_initial,
  File "/Users/lapshov/Documents/dve/lib/python3.4/site-packages/django/db/migrations/executor.py", line 115, in migrate
    state = self._migrate_all_forwards(state, plan, full_plan, fake=fake, fake_initial=fake_initial)
  File "/Users/lapshov/Documents/dve/lib/python3.4/site-packages/django/db/migrations/executor.py", line 145, in _migrate_all_forwards
    state = self.apply_migration(state, migration, fake=fake, fake_initial=fake_initial)
  File "/Users/lapshov/Documents/dve/lib/python3.4/site-packages/django/db/migrations/executor.py", line 244, in apply_migration
    state = migration.apply(state, schema_editor)
  File "/Users/lapshov/Documents/dve/lib/python3.4/site-packages/django/db/migrations/migration.py", line 129, in apply
    operation.database_forwards(self.app_label, schema_editor, old_state, project_state)
  File "/Users/lapshov/Documents/dve/lib/python3.4/site-packages/django/db/migrations/operations/fields.py", line 204, in database_forwards
    schema_editor.alter_field(from_model, from_field, to_field)
  File "/Users/lapshov/Documents/dve/lib/python3.4/site-packages/django/db/backends/base/schema.py", line 495, in alter_field
    old_db_params, new_db_params, strict)
  File "/Users/lapshov/Documents/dve/lib/python3.4/site-packages/django/db/backends/base/schema.py", line 678, in _alter_field
    self.execute(self._create_unique_sql(model, [new_field.column]))
  File "/Users/lapshov/Documents/dve/lib/python3.4/site-packages/django/db/backends/base/schema.py", line 112, in execute
    cursor.execute(sql, params)
  File "/Users/lapshov/Documents/dve/lib/python3.4/site-packages/django/db/backends/utils.py", line 79, in execute
    return super(CursorDebugWrapper, self).execute(sql, params)
  File "/Users/lapshov/Documents/dve/lib/python3.4/site-packages/django/db/backends/utils.py", line 64, in execute
    return self.cursor.execute(sql, params)
  File "/Users/lapshov/Documents/dve/lib/python3.4/site-packages/django/db/utils.py", line 94, in __exit__
    six.reraise(dj_exc_type, dj_exc_value, traceback)
  File "/Users/lapshov/Documents/dve/lib/python3.4/site-packages/django/utils/six.py", line 685, in reraise
    raise value.with_traceback(tb)
  File "/Users/lapshov/Documents/dve/lib/python3.4/site-packages/django/db/backends/utils.py", line 64, in execute
    return self.cursor.execute(sql, params)
  File "/Users/lapshov/Documents/dve/lib/python3.4/site-packages/django/db/backends/mysql/base.py", line 110, in execute
    return self.cursor.execute(query, args)
  File "/Users/lapshov/Documents/dve/lib/python3.4/site-packages/MySQLdb/cursors.py", line 250, in execute
    self.errorhandler(self, exc, value)
  File "/Users/lapshov/Documents/dve/lib/python3.4/site-packages/MySQLdb/connections.py", line 42, in defaulterrorhandler
    raise errorvalue
  File "/Users/lapshov/Documents/dve/lib/python3.4/site-packages/MySQLdb/cursors.py", line 247, in execute
    res = self._query(query)
  File "/Users/lapshov/Documents/dve/lib/python3.4/site-packages/MySQLdb/cursors.py", line 411, in _query
    rowcount = self._do_query(q)
  File "/Users/lapshov/Documents/dve/lib/python3.4/site-packages/MySQLdb/cursors.py", line 374, in _do_query
    db.query(q)
  File "/Users/lapshov/Documents/dve/lib/python3.4/site-packages/MySQLdb/connections.py", line 270, in query
    _mysql.connection.query(self, query)
django.db.utils.OperationalError: (1061, "Duplicate key name 'enot_app_subscriber_email_ea48cecc_uniq'")
24.05 15:30:03> Admin Command Error: manage.py migrate
Traceback (most recent call last):
  File "/Users/lapshov/Documents/dve/lib/python3.4/site-packages/django/db/backends/utils.py", line 64, in execute
    return self.cursor.execute(sql, params)
  File "/Users/lapshov/Documents/dve/lib/python3.4/site-packages/django/db/backends/mysql/base.py", line 110, in execute
    return self.cursor.execute(query, args)
  File "/Users/lapshov/Documents/dve/lib/python3.4/site-packages/MySQLdb/cursors.py", line 250, in execute
    self.errorhandler(self, exc, value)
  File "/Users/lapshov/Documents/dve/lib/python3.4/site-packages/MySQLdb/connections.py", line 42, in defaulterrorhandler
    raise errorvalue
  File "/Users/lapshov/Documents/dve/lib/python3.4/site-packages/MySQLdb/cursors.py", line 247, in execute
    res = self._query(query)
  File "/Users/lapshov/Documents/dve/lib/python3.4/site-packages/MySQLdb/cursors.py", line 411, in _query
    rowcount = self._do_query(q)
  File "/Users/lapshov/Documents/dve/lib/python3.4/site-packages/MySQLdb/cursors.py", line 374, in _do_query
    db.query(q)
  File "/Users/lapshov/Documents/dve/lib/python3.4/site-packages/MySQLdb/connections.py", line 270, in query
    _mysql.connection.query(self, query)
_mysql_exceptions.OperationalError: (1061, "Duplicate key name 'enot_app_subscriber_email_ea48cecc_uniq'")

The above exception was the direct cause of the following exception:

Traceback (most recent call last):
  File "manage.py", line 26, in <module>
    execute_from_command_line(sys.argv)
  File "/Users/lapshov/Documents/dve/lib/python3.4/site-packages/django/core/management/__init__.py", line 367, in execute_from_command_line
    utility.execute()
  File "/Users/lapshov/Documents/dve/lib/python3.4/site-packages/django/core/management/__init__.py", line 359, in execute
    self.fetch_command(subcommand).run_from_argv(self.argv)
  File "/Users/lapshov/Documents/dve/lib/python3.4/site-packages/django/core/management/base.py", line 294, in run_from_argv
    self.execute(*args, **cmd_options)
  File "/Users/lapshov/Documents/dve/lib/python3.4/site-packages/django/core/management/base.py", line 345, in execute
    output = self.handle(*args, **options)
  File "/Users/lapshov/Documents/dve/lib/python3.4/site-packages/django/core/management/commands/migrate.py", line 204, in handle
    fake_initial=fake_initial,
  File "/Users/lapshov/Documents/dve/lib/python3.4/site-packages/django/db/migrations/executor.py", line 115, in migrate
    state = self._migrate_all_forwards(state, plan, full_plan, fake=fake, fake_initial=fake_initial)
  File "/Users/lapshov/Documents/dve/lib/python3.4/site-packages/django/db/migrations/executor.py", line 145, in _migrate_all_forwards
    state = self.apply_migration(state, migration, fake=fake, fake_initial=fake_initial)
  File "/Users/lapshov/Documents/dve/lib/python3.4/site-packages/django/db/migrations/executor.py", line 244, in apply_migration
    state = migration.apply(state, schema_editor)
  File "/Users/lapshov/Documents/dve/lib/python3.4/site-packages/django/db/migrations/migration.py", line 129, in apply
    operation.database_forwards(self.app_label, schema_editor, old_state, project_state)
  File "/Users/lapshov/Documents/dve/lib/python3.4/site-packages/django/db/migrations/operations/fields.py", line 204, in database_forwards
    schema_editor.alter_field(from_model, from_field, to_field)
  File "/Users/lapshov/Documents/dve/lib/python3.4/site-packages/django/db/backends/base/schema.py", line 495, in alter_field
    old_db_params, new_db_params, strict)
  File "/Users/lapshov/Documents/dve/lib/python3.4/site-packages/django/db/backends/base/schema.py", line 678, in _alter_field
    self.execute(self._create_unique_sql(model, [new_field.column]))
  File "/Users/lapshov/Documents/dve/lib/python3.4/site-packages/django/db/backends/base/schema.py", line 112, in execute
    cursor.execute(sql, params)
  File "/Users/lapshov/Documents/dve/lib/python3.4/site-packages/django/db/backends/utils.py", line 79, in execute
    return super(CursorDebugWrapper, self).execute(sql, params)
  File "/Users/lapshov/Documents/dve/lib/python3.4/site-packages/django/db/backends/utils.py", line 64, in execute
    return self.cursor.execute(sql, params)
  File "/Users/lapshov/Documents/dve/lib/python3.4/site-packages/django/db/utils.py", line 94, in __exit__
    six.reraise(dj_exc_type, dj_exc_value, traceback)
  File "/Users/lapshov/Documents/dve/lib/python3.4/site-packages/django/utils/six.py", line 685, in reraise
    raise value.with_traceback(tb)
  File "/Users/lapshov/Documents/dve/lib/python3.4/site-packages/django/db/backends/utils.py", line 64, in execute
    return self.cursor.execute(sql, params)
  File "/Users/lapshov/Documents/dve/lib/python3.4/site-packages/django/db/backends/mysql/base.py", line 110, in execute
    return self.cursor.execute(query, args)
  File "/Users/lapshov/Documents/dve/lib/python3.4/site-packages/MySQLdb/cursors.py", line 250, in execute
    self.errorhandler(self, exc, value)
  File "/Users/lapshov/Documents/dve/lib/python3.4/site-packages/MySQLdb/connections.py", line 42, in defaulterrorhandler
    raise errorvalue
  File "/Users/lapshov/Documents/dve/lib/python3.4/site-packages/MySQLdb/cursors.py", line 247, in execute
    res = self._query(query)
  File "/Users/lapshov/Documents/dve/lib/python3.4/site-packages/MySQLdb/cursors.py", line 411, in _query
    rowcount = self._do_query(q)
  File "/Users/lapshov/Documents/dve/lib/python3.4/site-packages/MySQLdb/cursors.py", line 374, in _do_query
    db.query(q)
  File "/Users/lapshov/Documents/dve/lib/python3.4/site-packages/MySQLdb/connections.py", line 270, in query
    _mysql.connection.query(self, query)
django.db.utils.OperationalError: (1061, "Duplicate key name 'enot_app_subscriber_email_ea48cecc_uniq'")
24.05 15:31:49> Admin Command Error: manage.py migrate
Traceback (most recent call last):
  File "/Users/lapshov/Documents/dve/lib/python3.4/site-packages/django/db/backends/utils.py", line 64, in execute
    return self.cursor.execute(sql, params)
  File "/Users/lapshov/Documents/dve/lib/python3.4/site-packages/django/db/backends/mysql/base.py", line 110, in execute
    return self.cursor.execute(query, args)
  File "/Users/lapshov/Documents/dve/lib/python3.4/site-packages/MySQLdb/cursors.py", line 250, in execute
    self.errorhandler(self, exc, value)
  File "/Users/lapshov/Documents/dve/lib/python3.4/site-packages/MySQLdb/connections.py", line 42, in defaulterrorhandler
    raise errorvalue
  File "/Users/lapshov/Documents/dve/lib/python3.4/site-packages/MySQLdb/cursors.py", line 247, in execute
    res = self._query(query)
  File "/Users/lapshov/Documents/dve/lib/python3.4/site-packages/MySQLdb/cursors.py", line 411, in _query
    rowcount = self._do_query(q)
  File "/Users/lapshov/Documents/dve/lib/python3.4/site-packages/MySQLdb/cursors.py", line 374, in _do_query
    db.query(q)
  File "/Users/lapshov/Documents/dve/lib/python3.4/site-packages/MySQLdb/connections.py", line 270, in query
    _mysql.connection.query(self, query)
_mysql_exceptions.OperationalError: (1061, "Duplicate key name 'enot_app_subscriber_email_ea48cecc_uniq'")

The above exception was the direct cause of the following exception:

Traceback (most recent call last):
  File "manage.py", line 26, in <module>
    execute_from_command_line(sys.argv)
  File "/Users/lapshov/Documents/dve/lib/python3.4/site-packages/django/core/management/__init__.py", line 367, in execute_from_command_line
    utility.execute()
  File "/Users/lapshov/Documents/dve/lib/python3.4/site-packages/django/core/management/__init__.py", line 359, in execute
    self.fetch_command(subcommand).run_from_argv(self.argv)
  File "/Users/lapshov/Documents/dve/lib/python3.4/site-packages/django/core/management/base.py", line 294, in run_from_argv
    self.execute(*args, **cmd_options)
  File "/Users/lapshov/Documents/dve/lib/python3.4/site-packages/django/core/management/base.py", line 345, in execute
    output = self.handle(*args, **options)
  File "/Users/lapshov/Documents/dve/lib/python3.4/site-packages/django/core/management/commands/migrate.py", line 204, in handle
    fake_initial=fake_initial,
  File "/Users/lapshov/Documents/dve/lib/python3.4/site-packages/django/db/migrations/executor.py", line 115, in migrate
    state = self._migrate_all_forwards(state, plan, full_plan, fake=fake, fake_initial=fake_initial)
  File "/Users/lapshov/Documents/dve/lib/python3.4/site-packages/django/db/migrations/executor.py", line 145, in _migrate_all_forwards
    state = self.apply_migration(state, migration, fake=fake, fake_initial=fake_initial)
  File "/Users/lapshov/Documents/dve/lib/python3.4/site-packages/django/db/migrations/executor.py", line 244, in apply_migration
    state = migration.apply(state, schema_editor)
  File "/Users/lapshov/Documents/dve/lib/python3.4/site-packages/django/db/migrations/migration.py", line 129, in apply
    operation.database_forwards(self.app_label, schema_editor, old_state, project_state)
  File "/Users/lapshov/Documents/dve/lib/python3.4/site-packages/django/db/migrations/operations/fields.py", line 204, in database_forwards
    schema_editor.alter_field(from_model, from_field, to_field)
  File "/Users/lapshov/Documents/dve/lib/python3.4/site-packages/django/db/backends/base/schema.py", line 495, in alter_field
    old_db_params, new_db_params, strict)
  File "/Users/lapshov/Documents/dve/lib/python3.4/site-packages/django/db/backends/base/schema.py", line 678, in _alter_field
    self.execute(self._create_unique_sql(model, [new_field.column]))
  File "/Users/lapshov/Documents/dve/lib/python3.4/site-packages/django/db/backends/base/schema.py", line 112, in execute
    cursor.execute(sql, params)
  File "/Users/lapshov/Documents/dve/lib/python3.4/site-packages/django/db/backends/utils.py", line 79, in execute
    return super(CursorDebugWrapper, self).execute(sql, params)
  File "/Users/lapshov/Documents/dve/lib/python3.4/site-packages/django/db/backends/utils.py", line 64, in execute
    return self.cursor.execute(sql, params)
  File "/Users/lapshov/Documents/dve/lib/python3.4/site-packages/django/db/utils.py", line 94, in __exit__
    six.reraise(dj_exc_type, dj_exc_value, traceback)
  File "/Users/lapshov/Documents/dve/lib/python3.4/site-packages/django/utils/six.py", line 685, in reraise
    raise value.with_traceback(tb)
  File "/Users/lapshov/Documents/dve/lib/python3.4/site-packages/django/db/backends/utils.py", line 64, in execute
    return self.cursor.execute(sql, params)
  File "/Users/lapshov/Documents/dve/lib/python3.4/site-packages/django/db/backends/mysql/base.py", line 110, in execute
    return self.cursor.execute(query, args)
  File "/Users/lapshov/Documents/dve/lib/python3.4/site-packages/MySQLdb/cursors.py", line 250, in execute
    self.errorhandler(self, exc, value)
  File "/Users/lapshov/Documents/dve/lib/python3.4/site-packages/MySQLdb/connections.py", line 42, in defaulterrorhandler
    raise errorvalue
  File "/Users/lapshov/Documents/dve/lib/python3.4/site-packages/MySQLdb/cursors.py", line 247, in execute
    res = self._query(query)
  File "/Users/lapshov/Documents/dve/lib/python3.4/site-packages/MySQLdb/cursors.py", line 411, in _query
    rowcount = self._do_query(q)
  File "/Users/lapshov/Documents/dve/lib/python3.4/site-packages/MySQLdb/cursors.py", line 374, in _do_query
    db.query(q)
  File "/Users/lapshov/Documents/dve/lib/python3.4/site-packages/MySQLdb/connections.py", line 270, in query
    _mysql.connection.query(self, query)
django.db.utils.OperationalError: (1061, "Duplicate key name 'enot_app_subscriber_email_ea48cecc_uniq'")
24.05 15:32:57> Admin Command Error: manage.py migrate
Traceback (most recent call last):
  File "/Users/lapshov/Documents/dve/lib/python3.4/site-packages/django/db/backends/utils.py", line 64, in execute
    return self.cursor.execute(sql, params)
  File "/Users/lapshov/Documents/dve/lib/python3.4/site-packages/django/db/backends/mysql/base.py", line 110, in execute
    return self.cursor.execute(query, args)
  File "/Users/lapshov/Documents/dve/lib/python3.4/site-packages/MySQLdb/cursors.py", line 250, in execute
    self.errorhandler(self, exc, value)
  File "/Users/lapshov/Documents/dve/lib/python3.4/site-packages/MySQLdb/connections.py", line 42, in defaulterrorhandler
    raise errorvalue
  File "/Users/lapshov/Documents/dve/lib/python3.4/site-packages/MySQLdb/cursors.py", line 247, in execute
    res = self._query(query)
  File "/Users/lapshov/Documents/dve/lib/python3.4/site-packages/MySQLdb/cursors.py", line 411, in _query
    rowcount = self._do_query(q)
  File "/Users/lapshov/Documents/dve/lib/python3.4/site-packages/MySQLdb/cursors.py", line 374, in _do_query
    db.query(q)
  File "/Users/lapshov/Documents/dve/lib/python3.4/site-packages/MySQLdb/connections.py", line 270, in query
    _mysql.connection.query(self, query)
_mysql_exceptions.OperationalError: (1061, "Duplicate key name 'enot_app_subscriber_email_ea48cecc_uniq'")

The above exception was the direct cause of the following exception:

Traceback (most recent call last):
  File "manage.py", line 26, in <module>
    execute_from_command_line(sys.argv)
  File "/Users/lapshov/Documents/dve/lib/python3.4/site-packages/django/core/management/__init__.py", line 367, in execute_from_command_line
    utility.execute()
  File "/Users/lapshov/Documents/dve/lib/python3.4/site-packages/django/core/management/__init__.py", line 359, in execute
    self.fetch_command(subcommand).run_from_argv(self.argv)
  File "/Users/lapshov/Documents/dve/lib/python3.4/site-packages/django/core/management/base.py", line 294, in run_from_argv
    self.execute(*args, **cmd_options)
  File "/Users/lapshov/Documents/dve/lib/python3.4/site-packages/django/core/management/base.py", line 345, in execute
    output = self.handle(*args, **options)
  File "/Users/lapshov/Documents/dve/lib/python3.4/site-packages/django/core/management/commands/migrate.py", line 204, in handle
    fake_initial=fake_initial,
  File "/Users/lapshov/Documents/dve/lib/python3.4/site-packages/django/db/migrations/executor.py", line 115, in migrate
    state = self._migrate_all_forwards(state, plan, full_plan, fake=fake, fake_initial=fake_initial)
  File "/Users/lapshov/Documents/dve/lib/python3.4/site-packages/django/db/migrations/executor.py", line 145, in _migrate_all_forwards
    state = self.apply_migration(state, migration, fake=fake, fake_initial=fake_initial)
  File "/Users/lapshov/Documents/dve/lib/python3.4/site-packages/django/db/migrations/executor.py", line 244, in apply_migration
    state = migration.apply(state, schema_editor)
  File "/Users/lapshov/Documents/dve/lib/python3.4/site-packages/django/db/migrations/migration.py", line 129, in apply
    operation.database_forwards(self.app_label, schema_editor, old_state, project_state)
  File "/Users/lapshov/Documents/dve/lib/python3.4/site-packages/django/db/migrations/operations/fields.py", line 204, in database_forwards
    schema_editor.alter_field(from_model, from_field, to_field)
  File "/Users/lapshov/Documents/dve/lib/python3.4/site-packages/django/db/backends/base/schema.py", line 495, in alter_field
    old_db_params, new_db_params, strict)
  File "/Users/lapshov/Documents/dve/lib/python3.4/site-packages/django/db/backends/base/schema.py", line 678, in _alter_field
    self.execute(self._create_unique_sql(model, [new_field.column]))
  File "/Users/lapshov/Documents/dve/lib/python3.4/site-packages/django/db/backends/base/schema.py", line 112, in execute
    cursor.execute(sql, params)
  File "/Users/lapshov/Documents/dve/lib/python3.4/site-packages/django/db/backends/utils.py", line 79, in execute
    return super(CursorDebugWrapper, self).execute(sql, params)
  File "/Users/lapshov/Documents/dve/lib/python3.4/site-packages/django/db/backends/utils.py", line 64, in execute
    return self.cursor.execute(sql, params)
  File "/Users/lapshov/Documents/dve/lib/python3.4/site-packages/django/db/utils.py", line 94, in __exit__
    six.reraise(dj_exc_type, dj_exc_value, traceback)
  File "/Users/lapshov/Documents/dve/lib/python3.4/site-packages/django/utils/six.py", line 685, in reraise
    raise value.with_traceback(tb)
  File "/Users/lapshov/Documents/dve/lib/python3.4/site-packages/django/db/backends/utils.py", line 64, in execute
    return self.cursor.execute(sql, params)
  File "/Users/lapshov/Documents/dve/lib/python3.4/site-packages/django/db/backends/mysql/base.py", line 110, in execute
    return self.cursor.execute(query, args)
  File "/Users/lapshov/Documents/dve/lib/python3.4/site-packages/MySQLdb/cursors.py", line 250, in execute
    self.errorhandler(self, exc, value)
  File "/Users/lapshov/Documents/dve/lib/python3.4/site-packages/MySQLdb/connections.py", line 42, in defaulterrorhandler
    raise errorvalue
  File "/Users/lapshov/Documents/dve/lib/python3.4/site-packages/MySQLdb/cursors.py", line 247, in execute
    res = self._query(query)
  File "/Users/lapshov/Documents/dve/lib/python3.4/site-packages/MySQLdb/cursors.py", line 411, in _query
    rowcount = self._do_query(q)
  File "/Users/lapshov/Documents/dve/lib/python3.4/site-packages/MySQLdb/cursors.py", line 374, in _do_query
    db.query(q)
  File "/Users/lapshov/Documents/dve/lib/python3.4/site-packages/MySQLdb/connections.py", line 270, in query
    _mysql.connection.query(self, query)
django.db.utils.OperationalError: (1061, "Duplicate key name 'enot_app_subscriber_email_ea48cecc_uniq'")
24.05 15:33:14> Admin Command Error: manage.py migrate
Traceback (most recent call last):
  File "/Users/lapshov/Documents/dve/lib/python3.4/site-packages/django/db/backends/utils.py", line 64, in execute
    return self.cursor.execute(sql, params)
  File "/Users/lapshov/Documents/dve/lib/python3.4/site-packages/django/db/backends/mysql/base.py", line 110, in execute
    return self.cursor.execute(query, args)
  File "/Users/lapshov/Documents/dve/lib/python3.4/site-packages/MySQLdb/cursors.py", line 250, in execute
    self.errorhandler(self, exc, value)
  File "/Users/lapshov/Documents/dve/lib/python3.4/site-packages/MySQLdb/connections.py", line 42, in defaulterrorhandler
    raise errorvalue
  File "/Users/lapshov/Documents/dve/lib/python3.4/site-packages/MySQLdb/cursors.py", line 247, in execute
    res = self._query(query)
  File "/Users/lapshov/Documents/dve/lib/python3.4/site-packages/MySQLdb/cursors.py", line 411, in _query
    rowcount = self._do_query(q)
  File "/Users/lapshov/Documents/dve/lib/python3.4/site-packages/MySQLdb/cursors.py", line 374, in _do_query
    db.query(q)
  File "/Users/lapshov/Documents/dve/lib/python3.4/site-packages/MySQLdb/connections.py", line 270, in query
    _mysql.connection.query(self, query)
_mysql_exceptions.OperationalError: (1061, "Duplicate key name 'enot_app_subscriber_hsh_d2ee0937_uniq'")

The above exception was the direct cause of the following exception:

Traceback (most recent call last):
  File "manage.py", line 26, in <module>
    execute_from_command_line(sys.argv)
  File "/Users/lapshov/Documents/dve/lib/python3.4/site-packages/django/core/management/__init__.py", line 367, in execute_from_command_line
    utility.execute()
  File "/Users/lapshov/Documents/dve/lib/python3.4/site-packages/django/core/management/__init__.py", line 359, in execute
    self.fetch_command(subcommand).run_from_argv(self.argv)
  File "/Users/lapshov/Documents/dve/lib/python3.4/site-packages/django/core/management/base.py", line 294, in run_from_argv
    self.execute(*args, **cmd_options)
  File "/Users/lapshov/Documents/dve/lib/python3.4/site-packages/django/core/management/base.py", line 345, in execute
    output = self.handle(*args, **options)
  File "/Users/lapshov/Documents/dve/lib/python3.4/site-packages/django/core/management/commands/migrate.py", line 204, in handle
    fake_initial=fake_initial,
  File "/Users/lapshov/Documents/dve/lib/python3.4/site-packages/django/db/migrations/executor.py", line 115, in migrate
    state = self._migrate_all_forwards(state, plan, full_plan, fake=fake, fake_initial=fake_initial)
  File "/Users/lapshov/Documents/dve/lib/python3.4/site-packages/django/db/migrations/executor.py", line 145, in _migrate_all_forwards
    state = self.apply_migration(state, migration, fake=fake, fake_initial=fake_initial)
  File "/Users/lapshov/Documents/dve/lib/python3.4/site-packages/django/db/migrations/executor.py", line 244, in apply_migration
    state = migration.apply(state, schema_editor)
  File "/Users/lapshov/Documents/dve/lib/python3.4/site-packages/django/db/migrations/migration.py", line 129, in apply
    operation.database_forwards(self.app_label, schema_editor, old_state, project_state)
  File "/Users/lapshov/Documents/dve/lib/python3.4/site-packages/django/db/migrations/operations/fields.py", line 204, in database_forwards
    schema_editor.alter_field(from_model, from_field, to_field)
  File "/Users/lapshov/Documents/dve/lib/python3.4/site-packages/django/db/backends/base/schema.py", line 495, in alter_field
    old_db_params, new_db_params, strict)
  File "/Users/lapshov/Documents/dve/lib/python3.4/site-packages/django/db/backends/base/schema.py", line 678, in _alter_field
    self.execute(self._create_unique_sql(model, [new_field.column]))
  File "/Users/lapshov/Documents/dve/lib/python3.4/site-packages/django/db/backends/base/schema.py", line 112, in execute
    cursor.execute(sql, params)
  File "/Users/lapshov/Documents/dve/lib/python3.4/site-packages/django/db/backends/utils.py", line 79, in execute
    return super(CursorDebugWrapper, self).execute(sql, params)
  File "/Users/lapshov/Documents/dve/lib/python3.4/site-packages/django/db/backends/utils.py", line 64, in execute
    return self.cursor.execute(sql, params)
  File "/Users/lapshov/Documents/dve/lib/python3.4/site-packages/django/db/utils.py", line 94, in __exit__
    six.reraise(dj_exc_type, dj_exc_value, traceback)
  File "/Users/lapshov/Documents/dve/lib/python3.4/site-packages/django/utils/six.py", line 685, in reraise
    raise value.with_traceback(tb)
  File "/Users/lapshov/Documents/dve/lib/python3.4/site-packages/django/db/backends/utils.py", line 64, in execute
    return self.cursor.execute(sql, params)
  File "/Users/lapshov/Documents/dve/lib/python3.4/site-packages/django/db/backends/mysql/base.py", line 110, in execute
    return self.cursor.execute(query, args)
  File "/Users/lapshov/Documents/dve/lib/python3.4/site-packages/MySQLdb/cursors.py", line 250, in execute
    self.errorhandler(self, exc, value)
  File "/Users/lapshov/Documents/dve/lib/python3.4/site-packages/MySQLdb/connections.py", line 42, in defaulterrorhandler
    raise errorvalue
  File "/Users/lapshov/Documents/dve/lib/python3.4/site-packages/MySQLdb/cursors.py", line 247, in execute
    res = self._query(query)
  File "/Users/lapshov/Documents/dve/lib/python3.4/site-packages/MySQLdb/cursors.py", line 411, in _query
    rowcount = self._do_query(q)
  File "/Users/lapshov/Documents/dve/lib/python3.4/site-packages/MySQLdb/cursors.py", line 374, in _do_query
    db.query(q)
  File "/Users/lapshov/Documents/dve/lib/python3.4/site-packages/MySQLdb/connections.py", line 270, in query
    _mysql.connection.query(self, query)
django.db.utils.OperationalError: (1061, "Duplicate key name 'enot_app_subscriber_hsh_d2ee0937_uniq'")
