22.06 16:51:30> Admin Command Error: manage.py runserver
Traceback (most recent call last):
  File "manage.py", line 26, in <module>
    execute_from_command_line(sys.argv)
  File "/Library/Frameworks/Python.framework/Versions/3.4/lib/python3.4/site-packages/django/core/management/__init__.py", line 338, in execute_from_command_line
    utility.execute()
  File "/Library/Frameworks/Python.framework/Versions/3.4/lib/python3.4/site-packages/django/core/management/__init__.py", line 312, in execute
    django.setup()
  File "/Library/Frameworks/Python.framework/Versions/3.4/lib/python3.4/site-packages/django/__init__.py", line 18, in setup
    apps.populate(settings.INSTALLED_APPS)
  File "/Library/Frameworks/Python.framework/Versions/3.4/lib/python3.4/site-packages/django/apps/registry.py", line 85, in populate
    app_config = AppConfig.create(entry)
  File "/Library/Frameworks/Python.framework/Versions/3.4/lib/python3.4/site-packages/django/apps/config.py", line 86, in create
    module = import_module(entry)
  File "/Library/Frameworks/Python.framework/Versions/3.4/lib/python3.4/importlib/__init__.py", line 109, in import_module
    return _bootstrap._gcd_import(name[level:], package, level)
  File "<frozen importlib._bootstrap>", line 2254, in _gcd_import
  File "<frozen importlib._bootstrap>", line 2237, in _find_and_load
  File "<frozen importlib._bootstrap>", line 2224, in _find_and_load_unlocked
ImportError: No module named 'admin_view_permission'
22.06 19:36:59> Admin Command Error: manage.py force_rate_trips
Traceback (most recent call last):
  File "manage.py", line 26, in <module>
    execute_from_command_line(sys.argv)
  File "/Users/lapshov/Documents/dve/lib/python3.4/site-packages/django/core/management/__init__.py", line 367, in execute_from_command_line
    utility.execute()
  File "/Users/lapshov/Documents/dve/lib/python3.4/site-packages/django/core/management/__init__.py", line 359, in execute
    self.fetch_command(subcommand).run_from_argv(self.argv)
  File "/Users/lapshov/Documents/dve/lib/python3.4/site-packages/django/core/management/base.py", line 294, in run_from_argv
    self.execute(*args, **cmd_options)
  File "/Users/lapshov/Documents/dve/lib/python3.4/site-packages/django/core/management/base.py", line 345, in execute
    output = self.handle(*args, **options)
  File "/Users/lapshov/Documents/dve/enot/enot_app/management/commands/force_rate_trips.py", line 15, in handle
    r = review(t)
  File "/Users/lapshov/Documents/dve/enot/enot_app/rating.py", line 362, in review
    days_to = (trip.departure-now_in_moscow()).days
TypeError: can't subtract offset-naive and offset-aware datetimes
22.06 19:45:47> Bed time! zzz...
22.06 19:45:53> FORCED
22.06 19:45:53> Starting to load bids
22.06 19:45:54> Admin Command Error: manage.py load_bids --time 30 --force
Traceback (most recent call last):
  File "manage.py", line 26, in <module>
    execute_from_command_line(sys.argv)
  File "/Users/lapshov/Documents/dve/lib/python3.4/site-packages/django/core/management/__init__.py", line 367, in execute_from_command_line
    utility.execute()
  File "/Users/lapshov/Documents/dve/lib/python3.4/site-packages/django/core/management/__init__.py", line 359, in execute
    self.fetch_command(subcommand).run_from_argv(self.argv)
  File "/Users/lapshov/Documents/dve/lib/python3.4/site-packages/django/core/management/base.py", line 294, in run_from_argv
    self.execute(*args, **cmd_options)
  File "/Users/lapshov/Documents/dve/lib/python3.4/site-packages/django/core/management/base.py", line 345, in execute
    output = self.handle(*args, **options)
  File "/Users/lapshov/Documents/dve/enot/enot_app/management/commands/load_bids.py", line 87, in handle
    bid_cleanup(lt)
  File "/Users/lapshov/Documents/dve/enot/enot_app/management/commands/load_bids.py", line 31, in bid_cleanup
    | Q(departure_date=F('return_date'))
  File "/Users/lapshov/Documents/dve/lib/python3.4/site-packages/django/db/models/query.py", line 609, in delete
    deleted, _rows_count = collector.delete()
  File "/Users/lapshov/Documents/dve/lib/python3.4/site-packages/django/db/models/deletion.py", line 288, in delete
    count = qs._raw_delete(using=self.using)
  File "/Users/lapshov/Documents/dve/lib/python3.4/site-packages/django/db/models/query.py", line 623, in _raw_delete
    return sql.DeleteQuery(self.model).delete_qs(self, using)
  File "/Users/lapshov/Documents/dve/lib/python3.4/site-packages/django/db/models/sql/subqueries.py", line 81, in delete_qs
    cursor = self.get_compiler(using).execute_sql(CURSOR)
  File "/Users/lapshov/Documents/dve/lib/python3.4/site-packages/django/db/models/sql/compiler.py", line 824, in execute_sql
    sql, params = self.as_sql()
  File "/Users/lapshov/Documents/dve/lib/python3.4/site-packages/django/db/models/sql/compiler.py", line 1077, in as_sql
    where, params = self.compile(self.query.where)
  File "/Users/lapshov/Documents/dve/lib/python3.4/site-packages/django/db/models/sql/compiler.py", line 353, in compile
    sql, params = node.as_sql(self, self.connection)
  File "/Users/lapshov/Documents/dve/lib/python3.4/site-packages/django/db/models/sql/where.py", line 79, in as_sql
    sql, params = compiler.compile(child)
  File "/Users/lapshov/Documents/dve/lib/python3.4/site-packages/django/db/models/sql/compiler.py", line 353, in compile
    sql, params = node.as_sql(self, self.connection)
  File "/Users/lapshov/Documents/dve/lib/python3.4/site-packages/django/db/models/sql/where.py", line 79, in as_sql
    sql, params = compiler.compile(child)
  File "/Users/lapshov/Documents/dve/lib/python3.4/site-packages/django/db/models/sql/compiler.py", line 353, in compile
    sql, params = node.as_sql(self, self.connection)
  File "/Users/lapshov/Documents/dve/lib/python3.4/site-packages/django/db/models/lookups.py", line 156, in as_sql
    rhs_sql, rhs_params = self.process_rhs(compiler, connection)
  File "/Users/lapshov/Documents/dve/lib/python3.4/site-packages/django/db/models/lookups.py", line 92, in process_rhs
    return self.get_db_prep_lookup(value, connection)
  File "/Users/lapshov/Documents/dve/lib/python3.4/site-packages/django/db/models/lookups.py", line 182, in get_db_prep_lookup
    [get_db_prep_value(value, connection, prepared=True)]
  File "/Users/lapshov/Documents/dve/lib/python3.4/site-packages/django/db/models/fields/__init__.py", line 1439, in get_db_prep_value
    return connection.ops.adapt_datetimefield_value(value)
  File "/Users/lapshov/Documents/dve/lib/python3.4/site-packages/django/db/backends/mysql/operations.py", line 149, in adapt_datetimefield_value
    raise ValueError("MySQL backend does not support timezone-aware datetimes when USE_TZ is False.")
ValueError: MySQL backend does not support timezone-aware datetimes when USE_TZ is False.
22.06 19:46:42> FORCED
22.06 19:46:43> Something went wrong last time
22.06 19:47:07> FORCED
22.06 19:47:08> Starting to load bids
22.06 19:47:08> Sorting order: -start_date
22.06 19:47:08> LOAD_BIDS: Today's code: MOW
22.06 19:47:12> MOW >>> ROM
22.06 19:47:17> MOW >>> PAR
22.06 19:47:22> MOW >>> RIO
22.06 19:47:26> MOW >>> IST
22.06 19:47:31> MOW >>> LON
22.06 19:47:36> MOW >>> SPU
22.06 19:47:40> finished to load bids
22.06 19:47:59> Admin Command Error: manage.py force_rate_trips
Traceback (most recent call last):
  File "manage.py", line 26, in <module>
    execute_from_command_line(sys.argv)
  File "/Users/lapshov/Documents/dve/lib/python3.4/site-packages/django/core/management/__init__.py", line 367, in execute_from_command_line
    utility.execute()
  File "/Users/lapshov/Documents/dve/lib/python3.4/site-packages/django/core/management/__init__.py", line 359, in execute
    self.fetch_command(subcommand).run_from_argv(self.argv)
  File "/Users/lapshov/Documents/dve/lib/python3.4/site-packages/django/core/management/base.py", line 294, in run_from_argv
    self.execute(*args, **cmd_options)
  File "/Users/lapshov/Documents/dve/lib/python3.4/site-packages/django/core/management/base.py", line 345, in execute
    output = self.handle(*args, **options)
  File "/Users/lapshov/Documents/dve/enot/enot_app/management/commands/force_rate_trips.py", line 15, in handle
    r = review(t)
  File "/Users/lapshov/Documents/dve/enot/enot_app/rating.py", line 365, in review
    days_to = (tz.localize(trip.departure)-now_in_moscow()).days
  File "/Users/lapshov/Documents/dve/lib/python3.4/site-packages/pytz/tzinfo.py", line 304, in localize
    raise ValueError('Not naive datetime (tzinfo is already set)')
ValueError: Not naive datetime (tzinfo is already set)
22.06 19:51:59> FORCED
22.06 19:51:59> Starting to load bids
22.06 19:51:59> Sorting order: id
22.06 19:51:59> LOAD_BIDS: Today's code: MOW
22.06 19:52:03> MOW >>> ROM
22.06 19:52:07> MOW >>> PAR
22.06 19:52:11> MOW >>> RIO
22.06 19:52:16> MOW >>> LED
22.06 19:52:20> MOW >>> IST
22.06 19:52:24> MOW >>> LON
22.06 19:52:29> finished to load bids
22.06 19:55:04> Started trip loader task
22.06 19:55:04> 1: [122897] СПЛИТ | 14д | 2035 км | 14351р | R1251
22.06 19:55:04> 2: [122757] РИМ | 15д | 2377 км | 11170р | R1200
22.06 19:55:04> 3: [122807] РИО-ДЕ-ЖАНЕЙРО | 28д | 11542 км | 51861р | R1137
22.06 19:55:04> 4: [122777] ПАРИЖ | 6д | 2487 км | 12121р | R1035
22.06 19:55:04> 5: [122868] ЛОНДОН | 15д | 2489 км | 12343р | R903
22.06 19:55:04> 6: [122837] СТАМБУЛ | 186д | 1764 км | 7035р | R891
