05.05 12:43:02> Admin Command Error: manage.py tmp_slug
Traceback (most recent call last):
  File "manage.py", line 26, in <module>
    execute_from_command_line(sys.argv)
  File "/Users/lapshov/Documents/dve/lib/python3.4/site-packages/django/core/management/__init__.py", line 367, in execute_from_command_line
    utility.execute()
  File "/Users/lapshov/Documents/dve/lib/python3.4/site-packages/django/core/management/__init__.py", line 359, in execute
    self.fetch_command(subcommand).run_from_argv(self.argv)
  File "/Users/lapshov/Documents/dve/lib/python3.4/site-packages/django/core/management/base.py", line 294, in run_from_argv
    self.execute(*args, **cmd_options)
  File "/Users/lapshov/Documents/dve/lib/python3.4/site-packages/django/core/management/base.py", line 345, in execute
    output = self.handle(*args, **options)
  File "/Users/lapshov/Documents/dve/enot/enot_app/management/commands/tmp_slug.py", line 12, in handle
    trips = Trip.objects.all()
NameError: name 'Trip' is not defined
05.05 12:43:31> Admin Command Error: manage.py tmp_slug
Traceback (most recent call last):
  File "manage.py", line 26, in <module>
    execute_from_command_line(sys.argv)
  File "/Users/lapshov/Documents/dve/lib/python3.4/site-packages/django/core/management/__init__.py", line 367, in execute_from_command_line
    utility.execute()
  File "/Users/lapshov/Documents/dve/lib/python3.4/site-packages/django/core/management/__init__.py", line 359, in execute
    self.fetch_command(subcommand).run_from_argv(self.argv)
  File "/Users/lapshov/Documents/dve/lib/python3.4/site-packages/django/core/management/base.py", line 294, in run_from_argv
    self.execute(*args, **cmd_options)
  File "/Users/lapshov/Documents/dve/lib/python3.4/site-packages/django/core/management/base.py", line 345, in execute
    output = self.handle(*args, **options)
  File "/Users/lapshov/Documents/dve/enot/enot_app/management/commands/tmp_slug.py", line 15, in handle
    t.slug = get_hash(t.id)
  File "/Users/lapshov/Documents/dve/enot/enot_app/toolbox.py", line 19, in get_hash
    hsh.update(s.encode("utf-8"))
AttributeError: 'int' object has no attribute 'encode'
09.05 21:30:47> Bed time! zzz...
09.05 21:45:43> Bed time! zzz...
09.05 22:01:46> Bed time! zzz...
09.05 22:15:50> Bed time! zzz...
09.05 22:30:52> Bed time! zzz...
09.05 22:45:42> Bed time! zzz...
09.05 23:01:47> Bed time! zzz...
09.05 23:15:51> Bed time! zzz...
09.05 23:30:53> Bed time! zzz...
09.05 23:46:00> Bed time! zzz...
