23.06 09:16:35> Admin Command Error: manage.py localize
Traceback (most recent call last):
  File "manage.py", line 26, in <module>
    execute_from_command_line(sys.argv)
  File "/Users/lapshov/Documents/dve/lib/python3.4/site-packages/django/core/management/__init__.py", line 367, in execute_from_command_line
    utility.execute()
  File "/Users/lapshov/Documents/dve/lib/python3.4/site-packages/django/core/management/__init__.py", line 359, in execute
    self.fetch_command(subcommand).run_from_argv(self.argv)
  File "/Users/lapshov/Documents/dve/lib/python3.4/site-packages/django/core/management/base.py", line 294, in run_from_argv
    self.execute(*args, **cmd_options)
  File "/Users/lapshov/Documents/dve/lib/python3.4/site-packages/django/core/management/base.py", line 345, in execute
    output = self.handle(*args, **options)
  File "/Users/lapshov/Documents/dve/enot/enot_app/management/commands/localize.py", line 27, in handle
    t.departure = tz.localize(t.departure)
  File "/Users/lapshov/Documents/dve/lib/python3.4/site-packages/pytz/tzinfo.py", line 304, in localize
    raise ValueError('Not naive datetime (tzinfo is already set)')
ValueError: Not naive datetime (tzinfo is already set)
