05.06 20:47:11> Admin Command Error: manage.py makemigrations
Traceback (most recent call last):
  File "manage.py", line 26, in <module>
    execute_from_command_line(sys.argv)
  File "/Users/lapshov/Documents/dve/lib/python3.4/site-packages/django/core/management/__init__.py", line 367, in execute_from_command_line
    utility.execute()
  File "/Users/lapshov/Documents/dve/lib/python3.4/site-packages/django/core/management/__init__.py", line 359, in execute
    self.fetch_command(subcommand).run_from_argv(self.argv)
  File "/Users/lapshov/Documents/dve/lib/python3.4/site-packages/django/core/management/base.py", line 294, in run_from_argv
    self.execute(*args, **cmd_options)
  File "/Users/lapshov/Documents/dve/lib/python3.4/site-packages/django/core/management/base.py", line 342, in execute
    self.check()
  File "/Users/lapshov/Documents/dve/lib/python3.4/site-packages/django/core/management/base.py", line 374, in check
    include_deployment_checks=include_deployment_checks,
  File "/Users/lapshov/Documents/dve/lib/python3.4/site-packages/django/core/management/base.py", line 361, in _run_checks
    return checks.run_checks(**kwargs)
  File "/Users/lapshov/Documents/dve/lib/python3.4/site-packages/django/core/checks/registry.py", line 81, in run_checks
    new_errors = check(app_configs=app_configs)
  File "/Users/lapshov/Documents/dve/lib/python3.4/site-packages/django/core/checks/urls.py", line 14, in check_url_config
    return check_resolver(resolver)
  File "/Users/lapshov/Documents/dve/lib/python3.4/site-packages/django/core/checks/urls.py", line 24, in check_resolver
    for pattern in resolver.url_patterns:
  File "/Users/lapshov/Documents/dve/lib/python3.4/site-packages/django/utils/functional.py", line 35, in __get__
    res = instance.__dict__[self.name] = self.func(instance)
  File "/Users/lapshov/Documents/dve/lib/python3.4/site-packages/django/urls/resolvers.py", line 313, in url_patterns
    patterns = getattr(self.urlconf_module, "urlpatterns", self.urlconf_module)
  File "/Users/lapshov/Documents/dve/lib/python3.4/site-packages/django/utils/functional.py", line 35, in __get__
    res = instance.__dict__[self.name] = self.func(instance)
  File "/Users/lapshov/Documents/dve/lib/python3.4/site-packages/django/urls/resolvers.py", line 306, in urlconf_module
    return import_module(self.urlconf_name)
  File "/Users/lapshov/Documents/dve/lib/python3.4/importlib/__init__.py", line 109, in import_module
    return _bootstrap._gcd_import(name[level:], package, level)
  File "<frozen importlib._bootstrap>", line 2254, in _gcd_import
  File "<frozen importlib._bootstrap>", line 2237, in _find_and_load
  File "<frozen importlib._bootstrap>", line 2226, in _find_and_load_unlocked
  File "<frozen importlib._bootstrap>", line 1200, in _load_unlocked
  File "<frozen importlib._bootstrap>", line 1129, in _exec
  File "<frozen importlib._bootstrap>", line 1471, in exec_module
  File "<frozen importlib._bootstrap>", line 321, in _call_with_frames_removed
  File "/Users/lapshov/Documents/dve/enot/enot/urls.py", line 19, in <module>
    from djadmin2.site import djadmin2_site
  File "/Users/lapshov/Documents/dve/lib/python3.4/site-packages/djadmin2/site.py", line 1, in <module>
    from . import core
  File "/Users/lapshov/Documents/dve/lib/python3.4/site-packages/djadmin2/core.py", line 15, in <module>
    from . import types
  File "/Users/lapshov/Documents/dve/lib/python3.4/site-packages/djadmin2/types.py", line 19, in <module>
    from . import views
  File "/Users/lapshov/Documents/dve/lib/python3.4/site-packages/djadmin2/views.py", line 29, in <module>
    from .models import LogEntry
  File "/Users/lapshov/Documents/dve/lib/python3.4/site-packages/djadmin2/models.py", line 26, in <module>
    class LogEntry(models.Model):
  File "/Users/lapshov/Documents/dve/lib/python3.4/site-packages/django/db/models/base.py", line 113, in __new__
    "INSTALLED_APPS." % (module, name)
RuntimeError: Model class djadmin2.models.LogEntry doesn't declare an explicit app_label and isn't in an application in INSTALLED_APPS.
05.06 20:47:34> Admin Command Error: manage.py makemigrations
Traceback (most recent call last):
  File "manage.py", line 26, in <module>
    execute_from_command_line(sys.argv)
  File "/Users/lapshov/Documents/dve/lib/python3.4/site-packages/django/core/management/__init__.py", line 367, in execute_from_command_line
    utility.execute()
  File "/Users/lapshov/Documents/dve/lib/python3.4/site-packages/django/core/management/__init__.py", line 359, in execute
    self.fetch_command(subcommand).run_from_argv(self.argv)
  File "/Users/lapshov/Documents/dve/lib/python3.4/site-packages/django/core/management/base.py", line 294, in run_from_argv
    self.execute(*args, **cmd_options)
  File "/Users/lapshov/Documents/dve/lib/python3.4/site-packages/django/core/management/base.py", line 342, in execute
    self.check()
  File "/Users/lapshov/Documents/dve/lib/python3.4/site-packages/django/core/management/base.py", line 374, in check
    include_deployment_checks=include_deployment_checks,
  File "/Users/lapshov/Documents/dve/lib/python3.4/site-packages/django/core/management/base.py", line 361, in _run_checks
    return checks.run_checks(**kwargs)
  File "/Users/lapshov/Documents/dve/lib/python3.4/site-packages/django/core/checks/registry.py", line 81, in run_checks
    new_errors = check(app_configs=app_configs)
  File "/Users/lapshov/Documents/dve/lib/python3.4/site-packages/django/core/checks/urls.py", line 14, in check_url_config
    return check_resolver(resolver)
  File "/Users/lapshov/Documents/dve/lib/python3.4/site-packages/django/core/checks/urls.py", line 24, in check_resolver
    for pattern in resolver.url_patterns:
  File "/Users/lapshov/Documents/dve/lib/python3.4/site-packages/django/utils/functional.py", line 35, in __get__
    res = instance.__dict__[self.name] = self.func(instance)
  File "/Users/lapshov/Documents/dve/lib/python3.4/site-packages/django/urls/resolvers.py", line 313, in url_patterns
    patterns = getattr(self.urlconf_module, "urlpatterns", self.urlconf_module)
  File "/Users/lapshov/Documents/dve/lib/python3.4/site-packages/django/utils/functional.py", line 35, in __get__
    res = instance.__dict__[self.name] = self.func(instance)
  File "/Users/lapshov/Documents/dve/lib/python3.4/site-packages/django/urls/resolvers.py", line 306, in urlconf_module
    return import_module(self.urlconf_name)
  File "/Users/lapshov/Documents/dve/lib/python3.4/importlib/__init__.py", line 109, in import_module
    return _bootstrap._gcd_import(name[level:], package, level)
  File "<frozen importlib._bootstrap>", line 2254, in _gcd_import
  File "<frozen importlib._bootstrap>", line 2237, in _find_and_load
  File "<frozen importlib._bootstrap>", line 2226, in _find_and_load_unlocked
  File "<frozen importlib._bootstrap>", line 1200, in _load_unlocked
  File "<frozen importlib._bootstrap>", line 1129, in _exec
  File "<frozen importlib._bootstrap>", line 1471, in exec_module
  File "<frozen importlib._bootstrap>", line 321, in _call_with_frames_removed
  File "/Users/lapshov/Documents/dve/enot/enot/urls.py", line 19, in <module>
    from djadmin2.site import djadmin2_site
  File "/Users/lapshov/Documents/dve/lib/python3.4/site-packages/djadmin2/site.py", line 1, in <module>
    from . import core
  File "/Users/lapshov/Documents/dve/lib/python3.4/site-packages/djadmin2/core.py", line 15, in <module>
    from . import types
  File "/Users/lapshov/Documents/dve/lib/python3.4/site-packages/djadmin2/types.py", line 19, in <module>
    from . import views
  File "/Users/lapshov/Documents/dve/lib/python3.4/site-packages/djadmin2/views.py", line 29, in <module>
    from .models import LogEntry
  File "/Users/lapshov/Documents/dve/lib/python3.4/site-packages/djadmin2/models.py", line 26, in <module>
    class LogEntry(models.Model):
  File "/Users/lapshov/Documents/dve/lib/python3.4/site-packages/django/db/models/base.py", line 113, in __new__
    "INSTALLED_APPS." % (module, name)
RuntimeError: Model class djadmin2.models.LogEntry doesn't declare an explicit app_label and isn't in an application in INSTALLED_APPS.
05.06 20:48:17> Admin Command Error: manage.py makemigrations
Traceback (most recent call last):
  File "manage.py", line 26, in <module>
    execute_from_command_line(sys.argv)
  File "/Users/lapshov/Documents/dve/lib/python3.4/site-packages/django/core/management/__init__.py", line 367, in execute_from_command_line
    utility.execute()
  File "/Users/lapshov/Documents/dve/lib/python3.4/site-packages/django/core/management/__init__.py", line 359, in execute
    self.fetch_command(subcommand).run_from_argv(self.argv)
  File "/Users/lapshov/Documents/dve/lib/python3.4/site-packages/django/core/management/base.py", line 294, in run_from_argv
    self.execute(*args, **cmd_options)
  File "/Users/lapshov/Documents/dve/lib/python3.4/site-packages/django/core/management/base.py", line 342, in execute
    self.check()
  File "/Users/lapshov/Documents/dve/lib/python3.4/site-packages/django/core/management/base.py", line 374, in check
    include_deployment_checks=include_deployment_checks,
  File "/Users/lapshov/Documents/dve/lib/python3.4/site-packages/django/core/management/base.py", line 361, in _run_checks
    return checks.run_checks(**kwargs)
  File "/Users/lapshov/Documents/dve/lib/python3.4/site-packages/django/core/checks/registry.py", line 81, in run_checks
    new_errors = check(app_configs=app_configs)
  File "/Users/lapshov/Documents/dve/lib/python3.4/site-packages/django/core/checks/urls.py", line 14, in check_url_config
    return check_resolver(resolver)
  File "/Users/lapshov/Documents/dve/lib/python3.4/site-packages/django/core/checks/urls.py", line 24, in check_resolver
    for pattern in resolver.url_patterns:
  File "/Users/lapshov/Documents/dve/lib/python3.4/site-packages/django/utils/functional.py", line 35, in __get__
    res = instance.__dict__[self.name] = self.func(instance)
  File "/Users/lapshov/Documents/dve/lib/python3.4/site-packages/django/urls/resolvers.py", line 313, in url_patterns
    patterns = getattr(self.urlconf_module, "urlpatterns", self.urlconf_module)
  File "/Users/lapshov/Documents/dve/lib/python3.4/site-packages/django/utils/functional.py", line 35, in __get__
    res = instance.__dict__[self.name] = self.func(instance)
  File "/Users/lapshov/Documents/dve/lib/python3.4/site-packages/django/urls/resolvers.py", line 306, in urlconf_module
    return import_module(self.urlconf_name)
  File "/Users/lapshov/Documents/dve/lib/python3.4/importlib/__init__.py", line 109, in import_module
    return _bootstrap._gcd_import(name[level:], package, level)
  File "<frozen importlib._bootstrap>", line 2254, in _gcd_import
  File "<frozen importlib._bootstrap>", line 2237, in _find_and_load
  File "<frozen importlib._bootstrap>", line 2226, in _find_and_load_unlocked
  File "<frozen importlib._bootstrap>", line 1200, in _load_unlocked
  File "<frozen importlib._bootstrap>", line 1129, in _exec
  File "<frozen importlib._bootstrap>", line 1471, in exec_module
  File "<frozen importlib._bootstrap>", line 321, in _call_with_frames_removed
  File "/Users/lapshov/Documents/dve/enot/enot/urls.py", line 21, in <module>
    djadmin2_site.autodiscover()
  File "/Users/lapshov/Documents/dve/lib/python3.4/site-packages/djadmin2/core.py", line 124, in autodiscover
    import_module("%s.admin2" % app_name)
  File "/Users/lapshov/Documents/dve/lib/python3.4/importlib/__init__.py", line 109, in import_module
    return _bootstrap._gcd_import(name[level:], package, level)
  File "<frozen importlib._bootstrap>", line 2254, in _gcd_import
  File "<frozen importlib._bootstrap>", line 2237, in _find_and_load
  File "<frozen importlib._bootstrap>", line 2226, in _find_and_load_unlocked
  File "<frozen importlib._bootstrap>", line 1200, in _load_unlocked
  File "<frozen importlib._bootstrap>", line 1129, in _exec
  File "<frozen importlib._bootstrap>", line 1471, in exec_module
  File "<frozen importlib._bootstrap>", line 321, in _call_with_frames_removed
  File "/Users/lapshov/Documents/dve/lib/python3.4/site-packages/djadmin2/admin2.py", line 6, in <module>
    from django.contrib.sites.models import Site
  File "/Users/lapshov/Documents/dve/lib/python3.4/site-packages/django/contrib/sites/models.py", line 86, in <module>
    class Site(models.Model):
  File "/Users/lapshov/Documents/dve/lib/python3.4/site-packages/django/db/models/base.py", line 113, in __new__
    "INSTALLED_APPS." % (module, name)
RuntimeError: Model class django.contrib.sites.models.Site doesn't declare an explicit app_label and isn't in an application in INSTALLED_APPS.
05.06 20:58:20> Admin Command Error: manage.py collectstatic
Traceback (most recent call last):
  File "manage.py", line 26, in <module>
    execute_from_command_line(sys.argv)
  File "/Users/lapshov/Documents/dve/lib/python3.4/site-packages/django/core/management/__init__.py", line 367, in execute_from_command_line
    utility.execute()
  File "/Users/lapshov/Documents/dve/lib/python3.4/site-packages/django/core/management/__init__.py", line 359, in execute
    self.fetch_command(subcommand).run_from_argv(self.argv)
  File "/Users/lapshov/Documents/dve/lib/python3.4/site-packages/django/core/management/base.py", line 294, in run_from_argv
    self.execute(*args, **cmd_options)
  File "/Users/lapshov/Documents/dve/lib/python3.4/site-packages/django/core/management/base.py", line 345, in execute
    output = self.handle(*args, **options)
  File "/Users/lapshov/Documents/dve/lib/python3.4/site-packages/django/contrib/staticfiles/management/commands/collectstatic.py", line 193, in handle
    collected = self.collect()
  File "/Users/lapshov/Documents/dve/lib/python3.4/site-packages/django/contrib/staticfiles/management/commands/collectstatic.py", line 124, in collect
    handler(path, prefixed_path, storage)
  File "/Users/lapshov/Documents/dve/lib/python3.4/site-packages/django/contrib/staticfiles/management/commands/collectstatic.py", line 337, in copy_file
    if not self.delete_file(path, prefixed_path, source_storage):
  File "/Users/lapshov/Documents/dve/lib/python3.4/site-packages/django/contrib/staticfiles/management/commands/collectstatic.py", line 255, in delete_file
    if self.storage.exists(prefixed_path):
  File "/Users/lapshov/Documents/dve/lib/python3.4/site-packages/django/core/files/storage.py", line 394, in exists
    return os.path.exists(self.path(name))
  File "/Users/lapshov/Documents/dve/lib/python3.4/site-packages/django/contrib/staticfiles/storage.py", line 49, in path
    raise ImproperlyConfigured("You're using the staticfiles app "
django.core.exceptions.ImproperlyConfigured: You're using the staticfiles app without having set the STATIC_ROOT setting to a filesystem path.
